<?xml version="1.0" ?>
<sdf version="1.5">
  <world name="default">

    <!-- A global light source -->
    <include>
      <uri>model://sun</uri>
    </include>

    <!-- A ground plane -->
    <include>
      <uri>model://ground_plane</uri>
    </include>

    <!--  A velodyne -->
    <model name="volodyne_hdl-32">
      <link name="base">
        <pose>0 0 0.03 0 0 0</pose>
        <collision name="base_collision">
          <geometry>
            <cylinder>
              <radius>.04267</radius>
              <length>.05867</length>
            </cylinder>
          </geometry>
        </collision>
        <visual name="base_visual">
          <geometry>
            <cylinder>
              <radius>.04267</radius>
              <length>.05867</length>
            </cylinder>
          </geometry>
        </visual>
        <inertial>
          <mass>1.2</mass>
          <inertia>
            <ixx>0.001087473</ixx>
            <iyy>0.001087473</iyy>
            <izz>0.001092437</izz>
            <ixy>0</ixy>
            <ixz>0</ixz>
            <iyz>0</iyz>
          </inertia>
        </inertial>

      </link>

      <link name="top">
        <pose>0 0 0.095 0 0 0</pose>
        <collision name="top_collision">
          <geometry>
            <cylinder>
              <radius>.04267</radius>
              <length>.05867</length>
            </cylinder>
          </geometry>
        </collision>

        <visual name="top_visual">
          <geometry>
            <cylinder>
              <radius>.04267</radius>
              <length>.05867</length>
            </cylinder>
          </geometry>
        </visual>
        <inertial>
          <mass>0.1</mass>
          <inertia>
            <ixx>0.000090623</ixx>
            <iyy>0.000090623</iyy>
            <izz>0.000091036</izz>
            <ixy>0</ixy>
            <ixz>0</ixz>
            <iyz>0</iyz>
          </inertia>
        </inertial>
        <sensor type="ray" name="sensor">
          <pose>0 0 -0.004645 1.5707 0 0</pose>
          <visualize>true</visualize>
          <update_rate>30</update_rate>
          <ray>
            <scan>
              <horizontal>
                <samples>1</samples>
                <resolution>1</resolution>
                <min_angle>-0.001</min_angle>
                <max_angle>0.001</max_angle>
              </horizontal>
            </scan>
            <range>
              <min>0.05</min>
              <max>70</max>
              <resolution>0.02</resolution>
            </range>
          </ray>
        </sensor>
      </link>

      <joint type="revolute" name="joint">
        <pose>0 0 -0.036785 0 0 0</pose>
        <parent>base</parent>
        <child>top</child>
        <axis>
          <xyz>0 0 1</xyz>
          <limit>
            <!-- Use a very large number to indicate a continuous revolution -->
            <lower>-10000000000000000</lower>
            <upper>10000000000000000</upper>
          </limit>
        </axis>
      </joint>
    </model>
  </world>
</sdf>
